--------------------------------------------------------------------------
The library attempted to open the following supporting CUDA libraries,
but each of them failed.  CUDA-aware support is disabled.
libcuda.so.1: cannot open shared object file: No such file or directory
libcuda.dylib: cannot open shared object file: No such file or directory
/usr/lib64/libcuda.so.1: cannot open shared object file: No such file or directory
/usr/lib64/libcuda.dylib: cannot open shared object file: No such file or directory
If you are not interested in CUDA-aware support, then run with
--mca mpi_cuda_support 0 to suppress this message.  If you are interested
in CUDA-aware support, then try setting LD_LIBRARY_PATH to the location
of libcuda.so.1 to get passed this issue.
--------------------------------------------------------------------------
Traceback (most recent call last):
  File "/homes/cosinga/.local/lib/python3.7/site-packages/matplotlib/texmanager.py", line 305, in _run_checked_subprocess
    stderr=subprocess.STDOUT)
  File "/software/spack-software/2020.05.14/linux-rhel8-ivybridge/gcc-8.4.0/python-3.7.7-zgcjuclie3fiis4ljkrfp4c4j6fkoa62/lib/python3.7/subprocess.py", line 411, in check_output
    **kwargs).stdout
  File "/software/spack-software/2020.05.14/linux-rhel8-ivybridge/gcc-8.4.0/python-3.7.7-zgcjuclie3fiis4ljkrfp4c4j6fkoa62/lib/python3.7/subprocess.py", line 488, in run
    with Popen(*popenargs, **kwargs) as process:
  File "/software/spack-software/2020.05.14/linux-rhel8-ivybridge/gcc-8.4.0/python-3.7.7-zgcjuclie3fiis4ljkrfp4c4j6fkoa62/lib/python3.7/subprocess.py", line 800, in __init__
    restore_signals, start_new_session)
  File "/software/spack-software/2020.05.14/linux-rhel8-ivybridge/gcc-8.4.0/python-3.7.7-zgcjuclie3fiis4ljkrfp4c4j6fkoa62/lib/python3.7/subprocess.py", line 1551, in _execute_child
    raise child_exception_type(errno_num, err_msg, err_filename)
FileNotFoundError: [Errno 2] No such file or directory: 'dvipng': 'dvipng'

The above exception was the direct cause of the following exception:

Traceback (most recent call last):
  File "gr_histograms.py", line 226, in <module>
    main()
  File "gr_histograms.py", line 30, in main
    plt.savefig("/lustre/cosinga/gr_stmass.png")
  File "/homes/cosinga/.local/lib/python3.7/site-packages/matplotlib/pyplot.py", line 723, in savefig
    res = fig.savefig(*args, **kwargs)
  File "/homes/cosinga/.local/lib/python3.7/site-packages/matplotlib/figure.py", line 2203, in savefig
    self.canvas.print_figure(fname, **kwargs)
  File "/homes/cosinga/.local/lib/python3.7/site-packages/matplotlib/backend_bases.py", line 2105, in print_figure
    **kwargs)
  File "/homes/cosinga/.local/lib/python3.7/site-packages/matplotlib/backends/backend_agg.py", line 514, in print_png
    FigureCanvasAgg.draw(self)
  File "/homes/cosinga/.local/lib/python3.7/site-packages/matplotlib/backends/backend_agg.py", line 393, in draw
    self.figure.draw(self.renderer)
  File "/homes/cosinga/.local/lib/python3.7/site-packages/matplotlib/artist.py", line 38, in draw_wrapper
    return draw(artist, renderer, *args, **kwargs)
  File "/homes/cosinga/.local/lib/python3.7/site-packages/matplotlib/figure.py", line 1736, in draw
    renderer, self, artists, self.suppressComposite)
  File "/homes/cosinga/.local/lib/python3.7/site-packages/matplotlib/image.py", line 137, in _draw_list_compositing_images
    a.draw(renderer)
  File "/homes/cosinga/.local/lib/python3.7/site-packages/matplotlib/artist.py", line 38, in draw_wrapper
    return draw(artist, renderer, *args, **kwargs)
  File "/homes/cosinga/.local/lib/python3.7/site-packages/matplotlib/axes/_base.py", line 2630, in draw
    mimage._draw_list_compositing_images(renderer, self, artists)
  File "/homes/cosinga/.local/lib/python3.7/site-packages/matplotlib/image.py", line 137, in _draw_list_compositing_images
    a.draw(renderer)
  File "/homes/cosinga/.local/lib/python3.7/site-packages/matplotlib/artist.py", line 38, in draw_wrapper
    return draw(artist, renderer, *args, **kwargs)
  File "/homes/cosinga/.local/lib/python3.7/site-packages/matplotlib/axis.py", line 1232, in draw
    tick.draw(renderer)
  File "/homes/cosinga/.local/lib/python3.7/site-packages/matplotlib/artist.py", line 38, in draw_wrapper
    return draw(artist, renderer, *args, **kwargs)
  File "/homes/cosinga/.local/lib/python3.7/site-packages/matplotlib/axis.py", line 297, in draw
    artist.draw(renderer)
  File "/homes/cosinga/.local/lib/python3.7/site-packages/matplotlib/artist.py", line 38, in draw_wrapper
    return draw(artist, renderer, *args, **kwargs)
  File "/homes/cosinga/.local/lib/python3.7/site-packages/matplotlib/text.py", line 729, in draw
    mtext=mtext)
  File "/homes/cosinga/.local/lib/python3.7/site-packages/matplotlib/backends/backend_agg.py", line 229, in draw_tex
    Z = texmanager.get_grey(s, size, self.dpi)
  File "/homes/cosinga/.local/lib/python3.7/site-packages/matplotlib/texmanager.py", line 405, in get_grey
    pngfile = self.make_png(tex, fontsize, dpi)
  File "/homes/cosinga/.local/lib/python3.7/site-packages/matplotlib/texmanager.py", line 396, in make_png
    "-T", "tight", "-o", pngfile, dvifile], tex)
  File "/homes/cosinga/.local/lib/python3.7/site-packages/matplotlib/texmanager.py", line 309, in _run_checked_subprocess
    'found'.format(command[0])) from exc
RuntimeError: Failed to process string with tex because dvipng could not be found
